ply
format ascii 1.0
comment : MagicaVoxel @ Ephtracy
element vertex 912
property float x
property float y
property float z
property uchar red
property uchar green
property uchar blue
end_header
-16 -16 0 0 238 0
-15 -16 0 0 238 0
-14 -16 0 0 238 0
-13 -16 0 0 238 0
-12 -16 0 0 238 0
-11 -16 0 0 238 0
-7 -16 0 0 238 0
6 -16 0 0 238 0
10 -16 0 0 238 0
11 -16 0 0 238 0
12 -16 0 0 238 0
13 -16 0 0 238 0
14 -16 0 0 238 0
15 -16 0 0 238 0
-16 -15 0 0 238 0
-11 -15 0 0 238 0
-7 -15 0 0 238 0
6 -15 0 0 238 0
10 -15 0 0 238 0
15 -15 0 0 238 0
-16 -14 0 0 238 0
15 -14 0 0 238 0
-16 -13 0 0 238 0
15 -13 0 0 238 0
-16 -12 0 0 238 0
15 -12 0 0 238 0
-16 -11 0 0 238 0
15 -11 0 0 238 0
-16 -10 0 0 238 0
15 -10 0 0 238 0
-16 -9 0 0 238 0
15 -9 0 0 238 0
-16 -8 0 0 238 0
15 -8 0 0 238 0
-16 -7 0 0 238 0
15 -7 0 0 238 0
-16 -6 0 0 238 0
15 -6 0 0 238 0
-16 -5 0 0 238 0
15 -5 0 0 238 0
-16 -4 0 0 238 0
15 -4 0 0 238 0
-16 -3 0 0 238 0
15 -3 0 0 238 0
-16 -2 0 0 238 0
15 -2 0 0 238 0
-16 -1 0 0 238 0
15 -1 0 0 238 0
-16 0 0 0 238 0
15 0 0 0 238 0
-16 1 0 0 238 0
15 1 0 0 238 0
-16 2 0 0 238 0
-11 2 0 0 238 0
-7 2 0 0 238 0
6 2 0 0 238 0
10 2 0 0 238 0
15 2 0 0 238 0
-16 3 0 0 238 0
-15 3 0 0 238 0
-14 3 0 0 238 0
-13 3 0 0 238 0
-12 3 0 0 238 0
-11 3 0 0 238 0
-7 3 0 0 238 0
6 3 0 0 238 0
10 3 0 0 238 0
11 3 0 0 238 0
12 3 0 0 238 0
13 3 0 0 238 0
14 3 0 0 238 0
15 3 0 0 238 0
-16 -16 1 0 238 0
-15 -16 1 0 238 0
-14 -16 1 0 238 0
-13 -16 1 0 238 0
-12 -16 1 0 238 0
-11 -16 1 0 238 0
-8 -16 1 0 238 0
7 -16 1 0 238 0
10 -16 1 0 238 0
11 -16 1 0 238 0
12 -16 1 0 238 0
13 -16 1 0 238 0
14 -16 1 0 238 0
15 -16 1 0 238 0
-16 -15 1 0 238 0
-11 -15 1 0 238 0
-8 -15 1 0 238 0
7 -15 1 0 238 0
10 -15 1 0 238 0
15 -15 1 0 238 0
-16 -14 1 221 221 221
15 -14 1 221 221 221
-16 -13 1 0 238 0
15 -13 1 0 238 0
-16 -12 1 221 221 221
15 -12 1 221 221 221
-16 -11 1 0 238 0
15 -11 1 0 238 0
-16 -10 1 221 221 221
15 -10 1 221 221 221
-16 -9 1 0 238 0
15 -9 1 0 238 0
-16 -8 1 221 221 221
15 -8 1 221 221 221
-16 -7 1 0 238 0
15 -7 1 0 238 0
-16 -6 1 0 238 0
15 -6 1 0 238 0
-16 -5 1 221 221 221
15 -5 1 221 221 221
-16 -4 1 0 238 0
15 -4 1 0 238 0
-16 -3 1 221 221 221
15 -3 1 221 221 221
-16 -2 1 0 238 0
15 -2 1 0 238 0
-16 -1 1 221 221 221
15 -1 1 221 221 221
-16 0 1 0 238 0
15 0 1 0 238 0
-16 1 1 221 221 221
15 1 1 221 221 221
-16 2 1 0 238 0
-11 2 1 0 238 0
-8 2 1 0 238 0
7 2 1 0 238 0
10 2 1 0 238 0
15 2 1 0 238 0
-16 3 1 0 238 0
-15 3 1 0 238 0
-14 3 1 0 238 0
-13 3 1 0 238 0
-12 3 1 0 238 0
-11 3 1 0 238 0
-8 3 1 0 238 0
7 3 1 0 238 0
10 3 1 0 238 0
11 3 1 0 238 0
12 3 1 0 238 0
13 3 1 0 238 0
14 3 1 0 238 0
15 3 1 0 238 0
-16 -16 2 0 238 0
-15 -16 2 0 238 0
-14 -16 2 0 238 0
-13 -16 2 0 238 0
-12 -16 2 0 238 0
-11 -16 2 0 238 0
-9 -16 2 0 238 0
8 -16 2 0 238 0
10 -16 2 0 238 0
11 -16 2 0 238 0
12 -16 2 0 238 0
13 -16 2 0 238 0
14 -16 2 0 238 0
15 -16 2 0 238 0
-16 -15 2 0 238 0
-11 -15 2 0 238 0
-9 -15 2 0 238 0
8 -15 2 0 238 0
10 -15 2 0 238 0
15 -15 2 0 238 0
-16 -14 2 0 238 0
-11 -14 2 0 238 0
10 -14 2 0 238 0
15 -14 2 0 238 0
-16 -13 2 0 238 0
-11 -13 2 0 238 0
10 -13 2 0 238 0
15 -13 2 0 238 0
-16 -12 2 0 238 0
-11 -12 2 0 238 0
10 -12 2 0 238 0
15 -12 2 0 238 0
-16 -11 2 0 238 0
-11 -11 2 0 238 0
10 -11 2 0 238 0
15 -11 2 0 238 0
-16 -10 2 0 238 0
-11 -10 2 0 238 0
10 -10 2 0 238 0
15 -10 2 0 238 0
-16 -9 2 0 238 0
-11 -9 2 0 238 0
10 -9 2 0 238 0
15 -9 2 0 238 0
-16 -8 2 0 238 0
-11 -8 2 0 238 0
10 -8 2 0 238 0
15 -8 2 0 238 0
-16 -7 2 0 238 0
-11 -7 2 0 238 0
10 -7 2 0 238 0
15 -7 2 0 238 0
-16 -6 2 0 238 0
-11 -6 2 0 238 0
10 -6 2 0 238 0
15 -6 2 0 238 0
-16 -5 2 0 238 0
-11 -5 2 0 238 0
10 -5 2 0 238 0
15 -5 2 0 238 0
-16 -4 2 0 238 0
-11 -4 2 0 238 0
10 -4 2 0 238 0
15 -4 2 0 238 0
-16 -3 2 0 238 0
-11 -3 2 0 238 0
10 -3 2 0 238 0
15 -3 2 0 238 0
-16 -2 2 0 238 0
-11 -2 2 0 238 0
10 -2 2 0 238 0
15 -2 2 0 238 0
-16 -1 2 0 238 0
-11 -1 2 0 238 0
10 -1 2 0 238 0
15 -1 2 0 238 0
-16 0 2 0 238 0
-11 0 2 0 238 0
10 0 2 0 238 0
15 0 2 0 238 0
-16 1 2 0 238 0
-11 1 2 0 238 0
10 1 2 0 238 0
15 1 2 0 238 0
-16 2 2 0 238 0
-11 2 2 0 238 0
-9 2 2 0 238 0
8 2 2 0 238 0
10 2 2 0 238 0
15 2 2 0 238 0
-16 3 2 0 238 0
-15 3 2 0 238 0
-14 3 2 0 238 0
-13 3 2 0 238 0
-12 3 2 0 238 0
-11 3 2 0 238 0
-9 3 2 0 238 0
8 3 2 0 238 0
10 3 2 0 238 0
11 3 2 0 238 0
12 3 2 0 238 0
13 3 2 0 238 0
14 3 2 0 238 0
15 3 2 0 238 0
-15 -16 3 0 238 0
-14 -16 3 0 238 0
-13 -16 3 0 238 0
-12 -16 3 0 238 0
-11 -16 3 0 238 0
-10 -16 3 0 238 0
9 -16 3 0 238 0
10 -16 3 0 238 0
11 -16 3 0 238 0
12 -16 3 0 238 0
13 -16 3 0 238 0
14 -16 3 0 238 0
-15 -15 3 0 238 0
-14 -15 3 0 238 0
-13 -15 3 0 238 0
-12 -15 3 0 238 0
-11 -15 3 0 238 0
-10 -15 3 0 238 0
9 -15 3 0 238 0
10 -15 3 0 238 0
11 -15 3 0 238 0
12 -15 3 0 238 0
13 -15 3 0 238 0
14 -15 3 0 238 0
-15 -14 3 0 238 0
-14 -14 3 0 238 0
-13 -14 3 0 238 0
-12 -14 3 0 238 0
-11 -14 3 0 238 0
-10 -14 3 0 238 0
9 -14 3 0 238 0
10 -14 3 0 238 0
11 -14 3 0 238 0
12 -14 3 0 238 0
13 -14 3 0 238 0
14 -14 3 0 238 0
-15 -13 3 0 238 0
-14 -13 3 0 238 0
-13 -13 3 0 238 0
-12 -13 3 0 238 0
-11 -13 3 0 238 0
-10 -13 3 0 238 0
9 -13 3 0 238 0
10 -13 3 0 238 0
11 -13 3 0 238 0
12 -13 3 0 238 0
13 -13 3 0 238 0
14 -13 3 0 238 0
-15 -12 3 0 238 0
-14 -12 3 0 238 0
-13 -12 3 0 238 0
-12 -12 3 0 238 0
-11 -12 3 0 238 0
-10 -12 3 0 238 0
9 -12 3 0 238 0
10 -12 3 0 238 0
11 -12 3 0 238 0
12 -12 3 0 238 0
13 -12 3 0 238 0
14 -12 3 0 238 0
-15 -11 3 0 238 0
-14 -11 3 0 238 0
-13 -11 3 0 238 0
-12 -11 3 0 238 0
-11 -11 3 0 238 0
-10 -11 3 0 238 0
9 -11 3 0 238 0
10 -11 3 0 238 0
11 -11 3 0 238 0
12 -11 3 0 238 0
13 -11 3 0 238 0
14 -11 3 0 238 0
-15 -10 3 0 238 0
-14 -10 3 0 238 0
-13 -10 3 0 238 0
-12 -10 3 0 238 0
-11 -10 3 0 238 0
-10 -10 3 0 238 0
9 -10 3 0 238 0
10 -10 3 0 238 0
11 -10 3 0 238 0
12 -10 3 0 238 0
13 -10 3 0 238 0
14 -10 3 0 238 0
-15 -9 3 0 238 0
-14 -9 3 0 238 0
-13 -9 3 0 238 0
-12 -9 3 0 238 0
-11 -9 3 0 238 0
-10 -9 3 0 238 0
9 -9 3 0 238 0
10 -9 3 0 238 0
11 -9 3 0 238 0
12 -9 3 0 238 0
13 -9 3 0 238 0
14 -9 3 0 238 0
-15 -8 3 0 238 0
-14 -8 3 0 238 0
-13 -8 3 0 238 0
-12 -8 3 0 238 0
-11 -8 3 0 238 0
-10 -8 3 0 238 0
9 -8 3 0 238 0
10 -8 3 0 238 0
11 -8 3 0 238 0
12 -8 3 0 238 0
13 -8 3 0 238 0
14 -8 3 0 238 0
-15 -7 3 0 238 0
-14 -7 3 0 238 0
-13 -7 3 0 238 0
-12 -7 3 0 238 0
-11 -7 3 0 238 0
-10 -7 3 0 238 0
9 -7 3 0 238 0
10 -7 3 0 238 0
11 -7 3 0 238 0
12 -7 3 0 238 0
13 -7 3 0 238 0
14 -7 3 0 238 0
-15 -6 3 0 238 0
-14 -6 3 0 238 0
-13 -6 3 0 238 0
-12 -6 3 0 238 0
-11 -6 3 0 238 0
-10 -6 3 0 238 0
9 -6 3 0 238 0
10 -6 3 0 238 0
11 -6 3 0 238 0
12 -6 3 0 238 0
13 -6 3 0 238 0
14 -6 3 0 238 0
-15 -5 3 0 238 0
-14 -5 3 0 238 0
-13 -5 3 0 238 0
-12 -5 3 0 238 0
-11 -5 3 0 238 0
-10 -5 3 0 238 0
9 -5 3 0 238 0
10 -5 3 0 238 0
11 -5 3 0 238 0
12 -5 3 0 238 0
13 -5 3 0 238 0
14 -5 3 0 238 0
-15 -4 3 0 238 0
-14 -4 3 0 238 0
-13 -4 3 0 238 0
-12 -4 3 0 238 0
-11 -4 3 0 238 0
-10 -4 3 0 238 0
9 -4 3 0 238 0
10 -4 3 0 238 0
11 -4 3 0 238 0
12 -4 3 0 238 0
13 -4 3 0 238 0
14 -4 3 0 238 0
-15 -3 3 0 238 0
-14 -3 3 0 238 0
-13 -3 3 0 238 0
-12 -3 3 0 238 0
-11 -3 3 0 238 0
-10 -3 3 0 238 0
9 -3 3 0 238 0
10 -3 3 0 238 0
11 -3 3 0 238 0
12 -3 3 0 238 0
13 -3 3 0 238 0
14 -3 3 0 238 0
-15 -2 3 0 238 0
-14 -2 3 0 238 0
-13 -2 3 0 238 0
-12 -2 3 0 238 0
-11 -2 3 0 238 0
-10 -2 3 0 238 0
9 -2 3 0 238 0
10 -2 3 0 238 0
11 -2 3 0 238 0
12 -2 3 0 238 0
13 -2 3 0 238 0
14 -2 3 0 238 0
-15 -1 3 0 238 0
-14 -1 3 0 238 0
-13 -1 3 0 238 0
-12 -1 3 0 238 0
-11 -1 3 0 238 0
-10 -1 3 0 238 0
9 -1 3 0 238 0
10 -1 3 0 238 0
11 -1 3 0 238 0
12 -1 3 0 238 0
13 -1 3 0 238 0
14 -1 3 0 238 0
-15 0 3 0 238 0
-14 0 3 0 238 0
-13 0 3 0 238 0
-12 0 3 0 238 0
-11 0 3 0 238 0
-10 0 3 0 238 0
9 0 3 0 238 0
10 0 3 0 238 0
11 0 3 0 238 0
12 0 3 0 238 0
13 0 3 0 238 0
14 0 3 0 238 0
-15 1 3 0 238 0
-14 1 3 0 238 0
-13 1 3 0 238 0
-12 1 3 0 238 0
-11 1 3 0 238 0
-10 1 3 0 238 0
9 1 3 0 238 0
10 1 3 0 238 0
11 1 3 0 238 0
12 1 3 0 238 0
13 1 3 0 238 0
14 1 3 0 238 0
-15 2 3 0 238 0
-14 2 3 0 238 0
-13 2 3 0 238 0
-12 2 3 0 238 0
-11 2 3 0 238 0
-10 2 3 0 238 0
9 2 3 0 238 0
10 2 3 0 238 0
11 2 3 0 238 0
12 2 3 0 238 0
13 2 3 0 238 0
14 2 3 0 238 0
-15 3 3 0 238 0
-14 3 3 0 238 0
-13 3 3 0 238 0
-12 3 3 0 238 0
-11 3 3 0 238 0
-10 3 3 0 238 0
9 3 3 0 238 0
10 3 3 0 238 0
11 3 3 0 238 0
12 3 3 0 238 0
13 3 3 0 238 0
14 3 3 0 238 0
-16 -16 4 0 238 0
-15 -16 4 0 238 0
-14 -16 4 0 238 0
-13 -16 4 0 238 0
-12 -16 4 0 238 0
-11 -16 4 0 238 0
10 -16 4 0 238 0
11 -16 4 0 238 0
12 -16 4 0 238 0
13 -16 4 0 238 0
14 -16 4 0 238 0
15 -16 4 0 238 0
-16 -15 4 0 238 0
-11 -15 4 0 238 0
10 -15 4 0 238 0
15 -15 4 0 238 0
-16 -14 4 0 238 0
15 -14 4 0 238 0
-16 -13 4 0 238 0
15 -13 4 0 238 0
-16 -12 4 0 238 0
15 -12 4 0 238 0
-16 -11 4 0 238 0
15 -11 4 0 238 0
-16 -10 4 0 238 0
15 -10 4 0 238 0
-16 -9 4 0 238 0
15 -9 4 0 238 0
-16 -8 4 0 238 0
15 -8 4 0 238 0
-16 -7 4 0 238 0
15 -7 4 0 238 0
-16 -6 4 0 238 0
15 -6 4 0 238 0
-16 -5 4 0 238 0
15 -5 4 0 238 0
-16 -4 4 0 238 0
15 -4 4 0 238 0
-16 -3 4 0 238 0
15 -3 4 0 238 0
-16 -2 4 0 238 0
15 -2 4 0 238 0
-16 -1 4 0 238 0
15 -1 4 0 238 0
-16 0 4 0 238 0
15 0 4 0 238 0
-16 1 4 0 238 0
15 1 4 0 238 0
-16 2 4 0 238 0
-11 2 4 0 238 0
10 2 4 0 238 0
15 2 4 0 238 0
-16 3 4 0 238 0
-15 3 4 0 238 0
-14 3 4 0 238 0
-13 3 4 0 238 0
-12 3 4 0 238 0
-11 3 4 0 238 0
10 3 4 0 238 0
11 3 4 0 238 0
12 3 4 0 238 0
13 3 4 0 238 0
14 3 4 0 238 0
15 3 4 0 238 0
-16 -16 5 0 238 0
-15 -16 5 0 238 0
-14 -16 5 0 238 0
-13 -16 5 0 238 0
-12 -16 5 0 238 0
-11 -16 5 0 238 0
10 -16 5 0 238 0
11 -16 5 0 238 0
12 -16 5 0 238 0
13 -16 5 0 238 0
14 -16 5 0 238 0
15 -16 5 0 238 0
-16 -15 5 0 238 0
-11 -15 5 0 238 0
10 -15 5 0 238 0
15 -15 5 0 238 0
-16 -14 5 221 221 221
15 -14 5 221 221 221
-16 -13 5 0 238 0
15 -13 5 0 238 0
-16 -12 5 221 221 221
15 -12 5 221 221 221
-16 -11 5 0 238 0
15 -11 5 0 238 0
-16 -10 5 221 221 221
15 -10 5 221 221 221
-16 -9 5 0 238 0
15 -9 5 0 238 0
-16 -8 5 221 221 221
15 -8 5 221 221 221
-16 -7 5 0 238 0
15 -7 5 0 238 0
-16 -6 5 0 238 0
15 -6 5 0 238 0
-16 -5 5 221 221 221
15 -5 5 221 221 221
-16 -4 5 0 238 0
15 -4 5 0 238 0
-16 -3 5 221 221 221
15 -3 5 221 221 221
-16 -2 5 0 238 0
15 -2 5 0 238 0
-16 -1 5 221 221 221
15 -1 5 221 221 221
-16 0 5 0 238 0
15 0 5 0 238 0
-16 1 5 221 221 221
15 1 5 221 221 221
-16 2 5 0 238 0
-11 2 5 0 238 0
10 2 5 0 238 0
15 2 5 0 238 0
-16 3 5 0 238 0
-15 3 5 0 238 0
-14 3 5 0 238 0
-13 3 5 0 238 0
-12 3 5 0 238 0
-11 3 5 0 238 0
10 3 5 0 238 0
11 3 5 0 238 0
12 3 5 0 238 0
13 3 5 0 238 0
14 3 5 0 238 0
15 3 5 0 238 0
-16 -16 6 0 238 0
-15 -16 6 0 238 0
-14 -16 6 0 238 0
-13 -16 6 0 238 0
-12 -16 6 0 238 0
-11 -16 6 0 238 0
10 -16 6 0 238 0
11 -16 6 0 238 0
12 -16 6 0 238 0
13 -16 6 0 238 0
14 -16 6 0 238 0
15 -16 6 0 238 0
-16 -15 6 0 238 0
-11 -15 6 0 238 0
10 -15 6 0 238 0
15 -15 6 0 238 0
-16 -14 6 0 238 0
-11 -14 6 0 238 0
10 -14 6 0 238 0
15 -14 6 0 238 0
-16 -13 6 0 238 0
-11 -13 6 0 238 0
10 -13 6 0 238 0
15 -13 6 0 238 0
-16 -12 6 0 238 0
-11 -12 6 0 238 0
10 -12 6 0 238 0
15 -12 6 0 238 0
-16 -11 6 0 238 0
-11 -11 6 0 238 0
10 -11 6 0 238 0
15 -11 6 0 238 0
-16 -10 6 0 238 0
-11 -10 6 0 238 0
10 -10 6 0 238 0
15 -10 6 0 238 0
-16 -9 6 0 238 0
-11 -9 6 0 238 0
10 -9 6 0 238 0
15 -9 6 0 238 0
-16 -8 6 0 238 0
-11 -8 6 0 238 0
10 -8 6 0 238 0
15 -8 6 0 238 0
-16 -7 6 0 238 0
-11 -7 6 0 238 0
10 -7 6 0 238 0
15 -7 6 0 238 0
-16 -6 6 0 238 0
-11 -6 6 0 238 0
10 -6 6 0 238 0
15 -6 6 0 238 0
-16 -5 6 0 238 0
-11 -5 6 0 238 0
10 -5 6 0 238 0
15 -5 6 0 238 0
-16 -4 6 0 238 0
-11 -4 6 0 238 0
10 -4 6 0 238 0
15 -4 6 0 238 0
-16 -3 6 0 238 0
-11 -3 6 0 238 0
10 -3 6 0 238 0
15 -3 6 0 238 0
-16 -2 6 0 238 0
-11 -2 6 0 238 0
10 -2 6 0 238 0
15 -2 6 0 238 0
-16 -1 6 0 238 0
-11 -1 6 0 238 0
10 -1 6 0 238 0
15 -1 6 0 238 0
-16 0 6 0 238 0
-11 0 6 0 238 0
10 0 6 0 238 0
15 0 6 0 238 0
-16 1 6 0 238 0
-11 1 6 0 238 0
10 1 6 0 238 0
15 1 6 0 238 0
-16 2 6 0 238 0
-11 2 6 0 238 0
10 2 6 0 238 0
15 2 6 0 238 0
-16 3 6 0 238 0
-15 3 6 0 238 0
-14 3 6 0 238 0
-13 3 6 0 238 0
-12 3 6 0 238 0
-11 3 6 0 238 0
10 3 6 0 238 0
11 3 6 0 238 0
12 3 6 0 238 0
13 3 6 0 238 0
14 3 6 0 238 0
15 3 6 0 238 0
-15 -16 7 0 238 0
-14 -16 7 0 238 0
-13 -16 7 0 238 0
-12 -16 7 0 238 0
-11 -16 7 0 238 0
10 -16 7 0 238 0
11 -16 7 0 238 0
12 -16 7 0 238 0
13 -16 7 0 238 0
14 -16 7 0 238 0
-15 -15 7 0 238 0
-14 -15 7 0 238 0
-13 -15 7 0 238 0
-12 -15 7 0 238 0
-11 -15 7 0 238 0
10 -15 7 0 238 0
11 -15 7 0 238 0
12 -15 7 0 238 0
13 -15 7 0 238 0
14 -15 7 0 238 0
-15 -14 7 0 238 0
-14 -14 7 0 238 0
-13 -14 7 0 238 0
-12 -14 7 0 238 0
-11 -14 7 0 238 0
10 -14 7 0 238 0
11 -14 7 0 238 0
12 -14 7 0 238 0
13 -14 7 0 238 0
14 -14 7 0 238 0
-15 -13 7 0 238 0
-14 -13 7 0 238 0
-13 -13 7 0 238 0
-12 -13 7 0 238 0
-11 -13 7 0 238 0
10 -13 7 0 238 0
11 -13 7 0 238 0
12 -13 7 0 238 0
13 -13 7 0 238 0
14 -13 7 0 238 0
-15 -12 7 0 238 0
-14 -12 7 0 238 0
-13 -12 7 0 238 0
-12 -12 7 0 238 0
-11 -12 7 0 238 0
10 -12 7 0 238 0
11 -12 7 0 238 0
12 -12 7 0 238 0
13 -12 7 0 238 0
14 -12 7 0 238 0
-15 -11 7 0 238 0
-14 -11 7 0 238 0
-13 -11 7 0 238 0
-12 -11 7 0 238 0
-11 -11 7 0 238 0
10 -11 7 0 238 0
11 -11 7 0 238 0
12 -11 7 0 238 0
13 -11 7 0 238 0
14 -11 7 0 238 0
-15 -10 7 0 238 0
-14 -10 7 0 238 0
-13 -10 7 0 238 0
-12 -10 7 0 238 0
-11 -10 7 0 238 0
10 -10 7 0 238 0
11 -10 7 0 238 0
12 -10 7 0 238 0
13 -10 7 0 238 0
14 -10 7 0 238 0
-15 -9 7 0 238 0
-14 -9 7 0 238 0
-13 -9 7 0 238 0
-12 -9 7 0 238 0
-11 -9 7 0 238 0
10 -9 7 0 238 0
11 -9 7 0 238 0
12 -9 7 0 238 0
13 -9 7 0 238 0
14 -9 7 0 238 0
-15 -8 7 0 238 0
-14 -8 7 0 238 0
-13 -8 7 0 238 0
-12 -8 7 0 238 0
-11 -8 7 0 238 0
10 -8 7 0 238 0
11 -8 7 0 238 0
12 -8 7 0 238 0
13 -8 7 0 238 0
14 -8 7 0 238 0
-15 -7 7 0 238 0
-14 -7 7 0 238 0
-13 -7 7 0 238 0
-12 -7 7 0 238 0
-11 -7 7 0 238 0
10 -7 7 0 238 0
11 -7 7 0 238 0
12 -7 7 0 238 0
13 -7 7 0 238 0
14 -7 7 0 238 0
-15 -6 7 0 238 0
-14 -6 7 0 238 0
-13 -6 7 0 238 0
-12 -6 7 0 238 0
-11 -6 7 0 238 0
10 -6 7 0 238 0
11 -6 7 0 238 0
12 -6 7 0 238 0
13 -6 7 0 238 0
14 -6 7 0 238 0
-15 -5 7 0 238 0
-14 -5 7 0 238 0
-13 -5 7 0 238 0
-12 -5 7 0 238 0
-11 -5 7 0 238 0
10 -5 7 0 238 0
11 -5 7 0 238 0
12 -5 7 0 238 0
13 -5 7 0 238 0
14 -5 7 0 238 0
-15 -4 7 0 238 0
-14 -4 7 0 238 0
-13 -4 7 0 238 0
-12 -4 7 0 238 0
-11 -4 7 0 238 0
10 -4 7 0 238 0
11 -4 7 0 238 0
12 -4 7 0 238 0
13 -4 7 0 238 0
14 -4 7 0 238 0
-15 -3 7 0 238 0
-14 -3 7 0 238 0
-13 -3 7 0 238 0
-12 -3 7 0 238 0
-11 -3 7 0 238 0
10 -3 7 0 238 0
11 -3 7 0 238 0
12 -3 7 0 238 0
13 -3 7 0 238 0
14 -3 7 0 238 0
-15 -2 7 0 238 0
-14 -2 7 0 238 0
-13 -2 7 0 238 0
-12 -2 7 0 238 0
-11 -2 7 0 238 0
10 -2 7 0 238 0
11 -2 7 0 238 0
12 -2 7 0 238 0
13 -2 7 0 238 0
14 -2 7 0 238 0
-15 -1 7 0 238 0
-14 -1 7 0 238 0
-13 -1 7 0 238 0
-12 -1 7 0 238 0
-11 -1 7 0 238 0
10 -1 7 0 238 0
11 -1 7 0 238 0
12 -1 7 0 238 0
13 -1 7 0 238 0
14 -1 7 0 238 0
-15 0 7 0 238 0
-14 0 7 0 238 0
-13 0 7 0 238 0
-12 0 7 0 238 0
-11 0 7 0 238 0
10 0 7 0 238 0
11 0 7 0 238 0
12 0 7 0 238 0
13 0 7 0 238 0
14 0 7 0 238 0
-15 1 7 0 238 0
-14 1 7 0 238 0
-13 1 7 0 238 0
-12 1 7 0 238 0
-11 1 7 0 238 0
10 1 7 0 238 0
11 1 7 0 238 0
12 1 7 0 238 0
13 1 7 0 238 0
14 1 7 0 238 0
-15 2 7 0 238 0
-14 2 7 0 238 0
-13 2 7 0 238 0
-12 2 7 0 238 0
-11 2 7 0 238 0
10 2 7 0 238 0
11 2 7 0 238 0
12 2 7 0 238 0
13 2 7 0 238 0
14 2 7 0 238 0
-15 3 7 0 238 0
-14 3 7 0 238 0
-13 3 7 0 238 0
-12 3 7 0 238 0
-11 3 7 0 238 0
10 3 7 0 238 0
11 3 7 0 238 0
12 3 7 0 238 0
13 3 7 0 238 0
14 3 7 0 238 0
