ply
format ascii 1.0
comment : MagicaVoxel @ Ephtracy
element vertex 540
property float x
property float y
property float z
property uchar red
property uchar green
property uchar blue
end_header
0 0 -2 76 76 76
1 0 -2 76 76 76
2 0 -2 76 76 76
3 0 -2 76 76 76
4 0 -2 76 76 76
5 0 -2 76 76 76
6 0 -2 76 76 76
7 0 -2 76 76 76
8 0 -2 76 76 76
9 0 -2 76 76 76
10 0 -2 76 76 76
11 0 -2 76 76 76
12 0 -2 76 76 76
13 0 -2 76 76 76
14 0 -2 76 76 76
0 1 -2 76 76 76
1 1 -2 76 76 76
2 1 -2 76 76 76
3 1 -2 76 76 76
4 1 -2 76 76 76
5 1 -2 76 76 76
6 1 -2 76 76 76
7 1 -2 76 76 76
8 1 -2 76 76 76
9 1 -2 76 76 76
10 1 -2 76 76 76
11 1 -2 76 76 76
12 1 -2 76 76 76
13 1 -2 76 76 76
14 1 -2 76 76 76
0 2 -2 76 76 76
1 2 -2 76 76 76
2 2 -2 76 76 76
3 2 -2 76 76 76
4 2 -2 76 76 76
5 2 -2 76 76 76
6 2 -2 76 76 76
7 2 -2 76 76 76
8 2 -2 76 76 76
9 2 -2 76 76 76
10 2 -2 76 76 76
11 2 -2 76 76 76
12 2 -2 76 76 76
13 2 -2 76 76 76
14 2 -2 76 76 76
2 -7 -1 76 76 76
3 -7 -1 76 76 76
4 -7 -1 76 76 76
5 -7 -1 76 76 76
6 -7 -1 76 76 76
7 -7 -1 76 76 76
8 -7 -1 76 76 76
9 -7 -1 76 76 76
10 -7 -1 76 76 76
11 -7 -1 76 76 76
12 -7 -1 76 76 76
2 -6 -1 76 76 76
3 -6 -1 76 76 76
4 -6 -1 76 76 76
5 -6 -1 76 76 76
6 -6 -1 76 76 76
7 -6 -1 76 76 76
8 -6 -1 76 76 76
9 -6 -1 76 76 76
10 -6 -1 76 76 76
11 -6 -1 76 76 76
12 -6 -1 76 76 76
2 -5 -1 76 76 76
3 -5 -1 76 76 76
4 -5 -1 76 76 76
5 -5 -1 76 76 76
6 -5 -1 76 76 76
7 -5 -1 76 76 76
8 -5 -1 76 76 76
9 -5 -1 76 76 76
10 -5 -1 76 76 76
11 -5 -1 76 76 76
12 -5 -1 76 76 76
2 -4 -1 76 76 76
3 -4 -1 76 76 76
4 -4 -1 76 76 76
5 -4 -1 76 76 76
6 -4 -1 76 76 76
7 -4 -1 76 76 76
8 -4 -1 76 76 76
9 -4 -1 76 76 76
10 -4 -1 76 76 76
11 -4 -1 76 76 76
12 -4 -1 76 76 76
2 -3 -1 76 76 76
3 -3 -1 76 76 76
4 -3 -1 76 76 76
5 -3 -1 76 76 76
6 -3 -1 76 76 76
7 -3 -1 76 76 76
8 -3 -1 76 76 76
9 -3 -1 76 76 76
10 -3 -1 76 76 76
11 -3 -1 76 76 76
12 -3 -1 76 76 76
2 -2 -1 76 76 76
3 -2 -1 76 76 76
4 -2 -1 76 76 76
5 -2 -1 76 76 76
6 -2 -1 76 76 76
7 -2 -1 76 76 76
8 -2 -1 76 76 76
9 -2 -1 76 76 76
10 -2 -1 76 76 76
11 -2 -1 76 76 76
12 -2 -1 76 76 76
3 -1 -1 76 76 76
7 -1 -1 76 76 76
11 -1 -1 76 76 76
0 0 -1 153 153 153
1 0 -1 153 153 153
2 0 -1 153 153 153
3 0 -1 153 153 153
4 0 -1 153 153 153
5 0 -1 153 153 153
6 0 -1 153 153 153
7 0 -1 153 153 153
8 0 -1 153 153 153
9 0 -1 153 153 153
10 0 -1 153 153 153
11 0 -1 153 153 153
12 0 -1 153 153 153
13 0 -1 153 153 153
14 0 -1 153 153 153
0 1 -1 153 153 153
1 1 -1 153 153 153
2 1 -1 153 153 153
3 1 -1 153 153 153
4 1 -1 153 153 153
5 1 -1 153 153 153
6 1 -1 153 153 153
7 1 -1 153 153 153
8 1 -1 153 153 153
9 1 -1 153 153 153
10 1 -1 153 153 153
11 1 -1 153 153 153
12 1 -1 153 153 153
13 1 -1 153 153 153
14 1 -1 153 153 153
0 2 -1 153 153 153
1 2 -1 153 153 153
2 2 -1 153 153 153
3 2 -1 153 153 153
4 2 -1 153 153 153
5 2 -1 153 153 153
6 2 -1 153 153 153
7 2 -1 153 153 153
8 2 -1 153 153 153
9 2 -1 153 153 153
10 2 -1 153 153 153
11 2 -1 153 153 153
12 2 -1 153 153 153
13 2 -1 153 153 153
14 2 -1 153 153 153
3 3 -1 76 76 76
7 3 -1 76 76 76
11 3 -1 76 76 76
2 4 -1 76 76 76
3 4 -1 76 76 76
4 4 -1 76 76 76
5 4 -1 76 76 76
6 4 -1 76 76 76
7 4 -1 76 76 76
8 4 -1 76 76 76
9 4 -1 76 76 76
10 4 -1 76 76 76
11 4 -1 76 76 76
12 4 -1 76 76 76
2 5 -1 76 76 76
3 5 -1 76 76 76
4 5 -1 76 76 76
5 5 -1 76 76 76
6 5 -1 76 76 76
7 5 -1 76 76 76
8 5 -1 76 76 76
9 5 -1 76 76 76
10 5 -1 76 76 76
11 5 -1 76 76 76
12 5 -1 76 76 76
2 6 -1 76 76 76
3 6 -1 76 76 76
4 6 -1 76 76 76
5 6 -1 76 76 76
6 6 -1 76 76 76
7 6 -1 76 76 76
8 6 -1 76 76 76
9 6 -1 76 76 76
10 6 -1 76 76 76
11 6 -1 76 76 76
12 6 -1 76 76 76
2 7 -1 76 76 76
3 7 -1 76 76 76
4 7 -1 76 76 76
5 7 -1 76 76 76
6 7 -1 76 76 76
7 7 -1 76 76 76
8 7 -1 76 76 76
9 7 -1 76 76 76
10 7 -1 76 76 76
11 7 -1 76 76 76
12 7 -1 76 76 76
2 8 -1 76 76 76
3 8 -1 76 76 76
4 8 -1 76 76 76
5 8 -1 76 76 76
6 8 -1 76 76 76
7 8 -1 76 76 76
8 8 -1 76 76 76
9 8 -1 76 76 76
10 8 -1 76 76 76
11 8 -1 76 76 76
12 8 -1 76 76 76
2 9 -1 76 76 76
3 9 -1 76 76 76
4 9 -1 76 76 76
5 9 -1 76 76 76
6 9 -1 76 76 76
7 9 -1 76 76 76
8 9 -1 76 76 76
9 9 -1 76 76 76
10 9 -1 76 76 76
11 9 -1 76 76 76
12 9 -1 76 76 76
1 -7 0 127 204 25
2 -7 0 127 204 25
3 -7 0 127 204 25
4 -7 0 127 204 25
5 -7 0 127 204 25
6 -7 0 127 204 25
7 -7 0 127 204 25
8 -7 0 127 204 25
9 -7 0 127 204 25
10 -7 0 127 204 25
11 -7 0 127 204 25
12 -7 0 127 204 25
13 -7 0 127 204 25
1 -6 0 127 204 25
2 -6 0 222 222 108
12 -6 0 222 222 108
13 -6 0 127 204 25
1 -5 0 127 204 25
13 -5 0 127 204 25
1 -4 0 127 204 25
13 -4 0 127 204 25
1 -3 0 127 204 25
13 -3 0 127 204 25
2 -2 0 127 204 25
12 -2 0 127 204 25
2 4 0 127 204 25
12 4 0 127 204 25
1 5 0 127 204 25
13 5 0 127 204 25
1 6 0 127 204 25
13 6 0 127 204 25
1 7 0 127 204 25
13 7 0 127 204 25
1 8 0 127 204 25
2 8 0 222 222 108
12 8 0 222 222 108
13 8 0 127 204 25
1 9 0 127 204 25
2 9 0 127 204 25
3 9 0 127 204 25
4 9 0 127 204 25
5 9 0 127 204 25
6 9 0 127 204 25
7 9 0 127 204 25
8 9 0 127 204 25
9 9 0 127 204 25
10 9 0 127 204 25
11 9 0 127 204 25
12 9 0 127 204 25
13 9 0 127 204 25
1 -7 1 127 204 25
2 -7 1 178 102 229
3 -7 1 178 102 229
4 -7 1 178 102 229
5 -7 1 127 204 25
6 -7 1 178 102 229
7 -7 1 178 102 229
8 -7 1 178 102 229
9 -7 1 127 204 25
10 -7 1 178 102 229
11 -7 1 178 102 229
12 -7 1 178 102 229
13 -7 1 127 204 25
1 -6 1 127 204 25
2 -6 1 204 76 76
12 -6 1 204 76 76
13 -6 1 127 204 25
1 -5 1 127 204 25
13 -5 1 127 204 25
1 -4 1 127 204 25
13 -4 1 127 204 25
1 -3 1 127 204 25
13 -3 1 127 204 25
2 -2 1 127 204 25
12 -2 1 127 204 25
2 4 1 127 204 25
12 4 1 127 204 25
1 5 1 127 204 25
13 5 1 127 204 25
1 6 1 127 204 25
13 6 1 127 204 25
1 7 1 127 204 25
13 7 1 127 204 25
1 8 1 127 204 25
2 8 1 204 76 76
12 8 1 204 76 76
13 8 1 127 204 25
1 9 1 127 204 25
2 9 1 178 102 229
3 9 1 178 102 229
4 9 1 178 102 229
5 9 1 127 204 25
6 9 1 178 102 229
7 9 1 178 102 229
8 9 1 178 102 229
9 9 1 127 204 25
10 9 1 178 102 229
11 9 1 178 102 229
12 9 1 178 102 229
13 9 1 127 204 25
1 -7 2 127 204 25
2 -7 2 127 204 25
3 -7 2 127 204 25
4 -7 2 127 204 25
5 -7 2 127 204 25
6 -7 2 127 204 25
7 -7 2 127 204 25
8 -7 2 127 204 25
9 -7 2 127 204 25
10 -7 2 127 204 25
11 -7 2 127 204 25
12 -7 2 127 204 25
13 -7 2 127 204 25
1 -6 2 127 204 25
13 -6 2 127 204 25
1 -5 2 127 204 25
13 -5 2 127 204 25
1 -4 2 127 204 25
13 -4 2 127 204 25
1 -3 2 127 204 25
13 -3 2 127 204 25
2 -2 2 127 204 25
3 -2 2 127 204 25
4 -2 2 127 204 25
5 -2 2 127 204 25
6 -2 2 127 204 25
7 -2 2 127 204 25
8 -2 2 127 204 25
9 -2 2 127 204 25
10 -2 2 127 204 25
11 -2 2 127 204 25
12 -2 2 127 204 25
2 4 2 127 204 25
3 4 2 127 204 25
4 4 2 127 204 25
5 4 2 127 204 25
6 4 2 127 204 25
7 4 2 127 204 25
8 4 2 127 204 25
9 4 2 127 204 25
10 4 2 127 204 25
11 4 2 127 204 25
12 4 2 127 204 25
1 5 2 127 204 25
13 5 2 127 204 25
1 6 2 127 204 25
13 6 2 127 204 25
1 7 2 127 204 25
13 7 2 127 204 25
1 8 2 127 204 25
13 8 2 127 204 25
1 9 2 127 204 25
2 9 2 127 204 25
3 9 2 127 204 25
4 9 2 127 204 25
5 9 2 127 204 25
6 9 2 127 204 25
7 9 2 127 204 25
8 9 2 127 204 25
9 9 2 127 204 25
10 9 2 127 204 25
11 9 2 127 204 25
12 9 2 127 204 25
13 9 2 127 204 25
2 -7 3 222 222 108
3 -7 3 222 222 108
4 -7 3 222 222 108
5 -7 3 222 222 108
6 -7 3 222 222 108
7 -7 3 222 222 108
8 -7 3 222 222 108
9 -7 3 222 222 108
10 -7 3 222 222 108
11 -7 3 222 222 108
12 -7 3 222 222 108
1 -6 3 222 222 108
2 -6 3 222 222 108
3 -6 3 222 222 108
4 -6 3 222 222 108
5 -6 3 222 222 108
6 -6 3 222 222 108
7 -6 3 222 222 108
8 -6 3 222 222 108
9 -6 3 222 222 108
10 -6 3 222 222 108
11 -6 3 222 222 108
12 -6 3 222 222 108
13 -6 3 222 222 108
1 -5 3 222 222 108
2 -5 3 222 222 108
3 -5 3 222 222 108
4 -5 3 222 222 108
5 -5 3 222 222 108
6 -5 3 222 222 108
7 -5 3 222 222 108
8 -5 3 222 222 108
9 -5 3 222 222 108
10 -5 3 222 222 108
11 -5 3 222 222 108
12 -5 3 222 222 108
13 -5 3 222 222 108
1 -4 3 222 222 108
2 -4 3 222 222 108
3 -4 3 222 222 108
4 -4 3 222 222 108
5 -4 3 222 222 108
6 -4 3 222 222 108
7 -4 3 222 222 108
8 -4 3 222 222 108
9 -4 3 222 222 108
10 -4 3 222 222 108
11 -4 3 222 222 108
12 -4 3 222 222 108
13 -4 3 222 222 108
1 -3 3 222 222 108
2 -3 3 222 222 108
3 -3 3 222 222 108
4 -3 3 222 222 108
5 -3 3 222 222 108
6 -3 3 222 222 108
7 -3 3 222 222 108
8 -3 3 222 222 108
9 -3 3 222 222 108
10 -3 3 222 222 108
11 -3 3 222 222 108
12 -3 3 222 222 108
13 -3 3 222 222 108
2 -2 3 222 222 108
3 -2 3 222 222 108
4 -2 3 222 222 108
5 -2 3 222 222 108
6 -2 3 222 222 108
7 -2 3 222 222 108
8 -2 3 222 222 108
9 -2 3 222 222 108
10 -2 3 222 222 108
11 -2 3 222 222 108
12 -2 3 222 222 108
2 4 3 222 222 108
3 4 3 222 222 108
4 4 3 222 222 108
5 4 3 222 222 108
6 4 3 222 222 108
7 4 3 222 222 108
8 4 3 222 222 108
9 4 3 222 222 108
10 4 3 222 222 108
11 4 3 222 222 108
12 4 3 222 222 108
1 5 3 222 222 108
2 5 3 222 222 108
3 5 3 222 222 108
4 5 3 222 222 108
5 5 3 222 222 108
6 5 3 222 222 108
7 5 3 222 222 108
8 5 3 222 222 108
9 5 3 222 222 108
10 5 3 222 222 108
11 5 3 222 222 108
12 5 3 222 222 108
13 5 3 222 222 108
1 6 3 222 222 108
2 6 3 222 222 108
3 6 3 222 222 108
4 6 3 222 222 108
5 6 3 222 222 108
6 6 3 222 222 108
7 6 3 222 222 108
8 6 3 222 222 108
9 6 3 222 222 108
10 6 3 222 222 108
11 6 3 222 222 108
12 6 3 222 222 108
13 6 3 222 222 108
1 7 3 222 222 108
2 7 3 222 222 108
3 7 3 222 222 108
4 7 3 222 222 108
5 7 3 222 222 108
6 7 3 222 222 108
7 7 3 222 222 108
8 7 3 222 222 108
9 7 3 222 222 108
10 7 3 222 222 108
11 7 3 222 222 108
12 7 3 222 222 108
13 7 3 222 222 108
1 8 3 222 222 108
2 8 3 222 222 108
3 8 3 222 222 108
4 8 3 222 222 108
5 8 3 222 222 108
6 8 3 222 222 108
7 8 3 222 222 108
8 8 3 222 222 108
9 8 3 222 222 108
10 8 3 222 222 108
11 8 3 222 222 108
12 8 3 222 222 108
13 8 3 222 222 108
2 9 3 222 222 108
3 9 3 222 222 108
4 9 3 222 222 108
5 9 3 222 222 108
6 9 3 222 222 108
7 9 3 222 222 108
8 9 3 222 222 108
9 9 3 222 222 108
10 9 3 222 222 108
11 9 3 222 222 108
12 9 3 222 222 108
