ply
format ascii 1.0
comment : MagicaVoxel @ Ephtracy
element vertex 96
property float x
property float y
property float z
property uchar red
property uchar green
property uchar blue
end_header
-3 0 -6 170 170 170
-2 0 -6 170 170 170
-4 1 -6 170 170 170
-3 1 -6 170 170 170
-2 1 -6 170 170 170
-1 1 -6 170 170 170
-4 2 -6 170 170 170
-3 2 -6 170 170 170
-2 2 -6 170 170 170
-1 2 -6 170 170 170
-3 3 -6 170 170 170
-2 3 -6 170 170 170
-3 0 -5 170 170 170
-2 0 -5 170 170 170
-4 1 -5 170 170 170
-3 1 -5 0 0 0
-2 1 -5 0 0 0
-1 1 -5 170 170 170
-4 2 -5 170 170 170
-3 2 -5 0 0 0
-2 2 -5 0 0 0
-1 2 -5 170 170 170
-3 3 -5 170 170 170
-2 3 -5 170 170 170
-3 0 -4 170 170 170
-2 0 -4 170 170 170
-4 1 -4 170 170 170
-3 1 -4 0 0 0
-2 1 -4 0 0 0
-1 1 -4 170 170 170
-4 2 -4 170 170 170
-3 2 -4 0 0 0
-2 2 -4 0 0 0
-1 2 -4 170 170 170
-3 3 -4 170 170 170
-2 3 -4 170 170 170
-3 0 -3 170 170 170
-2 0 -3 170 170 170
-4 1 -3 170 170 170
-3 1 -3 0 0 0
-2 1 -3 0 0 0
-1 1 -3 170 170 170
-4 2 -3 170 170 170
-3 2 -3 0 0 0
-2 2 -3 0 0 0
-1 2 -3 170 170 170
-3 3 -3 170 170 170
-2 3 -3 170 170 170
-3 0 -2 170 170 170
-2 0 -2 170 170 170
-4 1 -2 170 170 170
-3 1 -2 0 0 0
-2 1 -2 0 0 0
-1 1 -2 170 170 170
-4 2 -2 170 170 170
-3 2 -2 0 0 0
-2 2 -2 0 0 0
-1 2 -2 170 170 170
-3 3 -2 170 170 170
-2 3 -2 170 170 170
-3 0 -1 170 170 170
-2 0 -1 170 170 170
-4 1 -1 170 170 170
-3 1 -1 0 0 0
-2 1 -1 0 0 0
-1 1 -1 170 170 170
-4 2 -1 170 170 170
-3 2 -1 0 0 0
-2 2 -1 0 0 0
-1 2 -1 170 170 170
-3 3 -1 170 170 170
-2 3 -1 170 170 170
-3 0 0 170 170 170
-2 0 0 170 170 170
-4 1 0 170 170 170
-3 1 0 0 0 0
-2 1 0 0 0 0
-1 1 0 170 170 170
-4 2 0 170 170 170
-3 2 0 0 0 0
-2 2 0 0 0 0
-1 2 0 170 170 170
-3 3 0 170 170 170
-2 3 0 170 170 170
-4 0 1 170 170 170
-3 0 1 170 170 170
-2 0 1 170 170 170
-1 0 1 170 170 170
-4 1 1 170 170 170
-1 1 1 170 170 170
-4 2 1 170 170 170
-1 2 1 170 170 170
-4 3 1 170 170 170
-3 3 1 170 170 170
-2 3 1 170 170 170
-1 3 1 170 170 170
