ply
format ascii 1.0
comment : MagicaVoxel @ Ephtracy
element vertex 557
property float x
property float y
property float z
property uchar red
property uchar green
property uchar blue
end_header
-2 -2 0 127 204 25
-1 -2 0 127 204 25
0 -2 0 127 204 25
1 -1 0 127 204 25
1 0 0 127 204 25
-2 1 0 127 204 25
-1 1 0 127 204 25
0 1 0 127 204 25
-2 -2 1 127 204 25
-1 -2 1 127 204 25
0 -2 1 127 204 25
1 -1 1 127 204 25
1 0 1 127 204 25
-2 1 1 127 204 25
-1 1 1 127 204 25
0 1 1 127 204 25
-2 -2 2 127 204 25
-1 -2 2 127 204 25
0 -2 2 127 204 25
1 -1 2 127 204 25
1 0 2 127 204 25
-2 1 2 127 204 25
-1 1 2 127 204 25
0 1 2 127 204 25
-2 -2 3 127 204 25
-1 -2 3 127 204 25
0 -2 3 127 204 25
-2 -1 3 127 204 25
1 -1 3 127 204 25
-2 0 3 127 204 25
1 0 3 127 204 25
-2 1 3 127 204 25
-1 1 3 127 204 25
0 1 3 127 204 25
-1 -2 4 127 204 25
0 -2 4 127 204 25
-2 -1 4 127 204 25
1 -1 4 127 204 25
-2 0 4 127 204 25
1 0 4 127 204 25
-1 1 4 127 204 25
0 1 4 127 204 25
-1 -2 5 127 204 25
0 -2 5 127 204 25
-2 -1 5 127 204 25
1 -1 5 127 204 25
-2 0 5 127 204 25
1 0 5 127 204 25
-1 1 5 127 204 25
0 1 5 127 204 25
-1 -2 6 127 204 25
0 -2 6 127 204 25
-2 -1 6 127 204 25
1 -1 6 127 204 25
-2 0 6 127 204 25
1 0 6 127 204 25
-1 1 6 127 204 25
0 1 6 127 204 25
-1 -2 7 127 204 25
0 -2 7 127 204 25
-2 -1 7 127 204 25
1 -1 7 127 204 25
-2 0 7 127 204 25
1 0 7 127 204 25
-1 1 7 127 204 25
0 1 7 127 204 25
-1 -2 8 127 204 25
0 -2 8 127 204 25
-2 -1 8 127 204 25
1 -1 8 127 204 25
-2 0 8 127 204 25
1 0 8 127 204 25
-1 1 8 127 204 25
0 1 8 127 204 25
-7 -7 9 127 204 25
-6 -7 9 127 204 25
-5 -7 9 127 204 25
-4 -7 9 127 204 25
-3 -7 9 127 204 25
-2 -7 9 127 204 25
-1 -7 9 127 204 25
0 -7 9 127 204 25
1 -7 9 127 204 25
2 -7 9 127 204 25
3 -7 9 127 204 25
4 -7 9 127 204 25
5 -7 9 127 204 25
6 -7 9 127 204 25
-7 -6 9 127 204 25
-6 -6 9 127 204 25
-5 -6 9 127 204 25
-4 -6 9 127 204 25
-3 -6 9 127 204 25
-2 -6 9 127 204 25
-1 -6 9 127 204 25
0 -6 9 127 204 25
1 -6 9 127 204 25
2 -6 9 127 204 25
3 -6 9 127 204 25
4 -6 9 127 204 25
5 -6 9 127 204 25
6 -6 9 127 204 25
-7 -5 9 127 204 25
-6 -5 9 127 204 25
-5 -5 9 127 204 25
-4 -5 9 127 204 25
-3 -5 9 127 204 25
-2 -5 9 127 204 25
-1 -5 9 127 204 25
0 -5 9 127 204 25
1 -5 9 127 204 25
2 -5 9 127 204 25
3 -5 9 127 204 25
4 -5 9 127 204 25
5 -5 9 127 204 25
6 -5 9 127 204 25
-7 -4 9 127 204 25
-6 -4 9 127 204 25
-5 -4 9 127 204 25
-4 -4 9 127 204 25
-3 -4 9 127 204 25
-2 -4 9 127 204 25
-1 -4 9 127 204 25
0 -4 9 127 204 25
1 -4 9 127 204 25
2 -4 9 127 204 25
3 -4 9 127 204 25
4 -4 9 127 204 25
5 -4 9 127 204 25
6 -4 9 127 204 25
-7 -3 9 127 204 25
-6 -3 9 127 204 25
-5 -3 9 127 204 25
-4 -3 9 127 204 25
-3 -3 9 127 204 25
-2 -3 9 127 204 25
-1 -3 9 127 204 25
0 -3 9 127 204 25
1 -3 9 127 204 25
2 -3 9 127 204 25
3 -3 9 127 204 25
4 -3 9 127 204 25
5 -3 9 127 204 25
6 -3 9 127 204 25
-7 -2 9 127 204 25
-6 -2 9 127 204 25
-5 -2 9 127 204 25
-4 -2 9 127 204 25
-3 -2 9 127 204 25
-2 -2 9 127 204 25
-1 -2 9 127 204 25
0 -2 9 127 204 25
1 -2 9 127 204 25
2 -2 9 127 204 25
3 -2 9 127 204 25
4 -2 9 127 204 25
5 -2 9 127 204 25
6 -2 9 127 204 25
-7 -1 9 127 204 25
-6 -1 9 127 204 25
-5 -1 9 127 204 25
-4 -1 9 127 204 25
-3 -1 9 127 204 25
-2 -1 9 127 204 25
1 -1 9 127 204 25
2 -1 9 127 204 25
3 -1 9 127 204 25
4 -1 9 127 204 25
5 -1 9 127 204 25
6 -1 9 127 204 25
-7 0 9 127 204 25
-6 0 9 127 204 25
-5 0 9 127 204 25
-4 0 9 127 204 25
-3 0 9 127 204 25
-2 0 9 127 204 25
1 0 9 127 204 25
2 0 9 127 204 25
3 0 9 127 204 25
4 0 9 127 204 25
5 0 9 127 204 25
6 0 9 127 204 25
-7 1 9 127 204 25
-6 1 9 127 204 25
-5 1 9 127 204 25
-4 1 9 127 204 25
-3 1 9 127 204 25
-2 1 9 127 204 25
-1 1 9 127 204 25
0 1 9 127 204 25
1 1 9 127 204 25
2 1 9 127 204 25
3 1 9 127 204 25
4 1 9 127 204 25
5 1 9 127 204 25
6 1 9 127 204 25
-7 2 9 127 204 25
-6 2 9 127 204 25
-5 2 9 127 204 25
-4 2 9 127 204 25
-3 2 9 127 204 25
-2 2 9 127 204 25
-1 2 9 127 204 25
0 2 9 127 204 25
1 2 9 127 204 25
2 2 9 127 204 25
3 2 9 127 204 25
4 2 9 127 204 25
5 2 9 127 204 25
6 2 9 127 204 25
-7 3 9 127 204 25
-6 3 9 127 204 25
-5 3 9 127 204 25
-4 3 9 127 204 25
-3 3 9 127 204 25
-2 3 9 127 204 25
-1 3 9 127 204 25
0 3 9 127 204 25
1 3 9 127 204 25
2 3 9 127 204 25
3 3 9 127 204 25
4 3 9 127 204 25
5 3 9 127 204 25
6 3 9 127 204 25
-7 4 9 127 204 25
-6 4 9 127 204 25
-5 4 9 127 204 25
-4 4 9 127 204 25
-3 4 9 127 204 25
-2 4 9 127 204 25
-1 4 9 127 204 25
0 4 9 127 204 25
1 4 9 127 204 25
2 4 9 127 204 25
3 4 9 127 204 25
4 4 9 127 204 25
5 4 9 127 204 25
6 4 9 127 204 25
-7 5 9 127 204 25
-6 5 9 127 204 25
-5 5 9 127 204 25
-4 5 9 127 204 25
-3 5 9 127 204 25
-2 5 9 127 204 25
-1 5 9 127 204 25
0 5 9 127 204 25
1 5 9 127 204 25
2 5 9 127 204 25
3 5 9 127 204 25
4 5 9 127 204 25
5 5 9 127 204 25
6 5 9 127 204 25
-7 6 9 127 204 25
-6 6 9 127 204 25
-5 6 9 127 204 25
-4 6 9 127 204 25
-3 6 9 127 204 25
-2 6 9 127 204 25
-1 6 9 127 204 25
0 6 9 127 204 25
1 6 9 127 204 25
2 6 9 127 204 25
3 6 9 127 204 25
4 6 9 127 204 25
5 6 9 127 204 25
6 6 9 127 204 25
-7 -8 10 127 204 25
-6 -8 10 127 204 25
-5 -8 10 127 204 25
-4 -8 10 127 204 25
-3 -8 10 127 204 25
-2 -8 10 127 204 25
-1 -8 10 127 204 25
0 -8 10 127 204 25
1 -8 10 127 204 25
2 -8 10 127 204 25
3 -8 10 127 204 25
4 -8 10 127 204 25
5 -8 10 127 204 25
6 -8 10 127 204 25
-8 -7 10 127 204 25
1 -7 10 127 204 25
7 -7 10 127 204 25
-8 -6 10 127 204 25
1 -6 10 127 204 25
7 -6 10 127 204 25
-8 -5 10 127 204 25
7 -5 10 127 204 25
-8 -4 10 127 204 25
7 -4 10 127 204 25
-8 -3 10 127 204 25
1 -3 10 127 204 25
7 -3 10 127 204 25
-8 -2 10 127 204 25
1 -2 10 127 204 25
7 -2 10 127 204 25
-8 -1 10 127 204 25
1 -1 10 127 204 25
7 -1 10 127 204 25
-8 0 10 127 204 25
1 0 10 127 204 25
2 0 10 127 204 25
3 0 10 127 204 25
6 0 10 127 204 25
7 0 10 127 204 25
-8 1 10 127 204 25
1 1 10 127 204 25
7 1 10 127 204 25
-8 2 10 127 204 25
1 2 10 127 204 25
7 2 10 127 204 25
-8 3 10 127 204 25
7 3 10 127 204 25
-8 4 10 127 204 25
7 4 10 127 204 25
-8 5 10 127 204 25
1 5 10 127 204 25
7 5 10 127 204 25
-8 6 10 127 204 25
1 6 10 127 204 25
7 6 10 127 204 25
-7 7 10 127 204 25
-6 7 10 127 204 25
-5 7 10 127 204 25
-4 7 10 127 204 25
-3 7 10 127 204 25
-2 7 10 127 204 25
-1 7 10 127 204 25
0 7 10 127 204 25
1 7 10 127 204 25
2 7 10 127 204 25
3 7 10 127 204 25
4 7 10 127 204 25
5 7 10 127 204 25
6 7 10 127 204 25
-7 -8 11 127 204 25
2 -8 11 127 204 25
3 -8 11 127 204 25
4 -8 11 127 204 25
5 -8 11 127 204 25
6 -8 11 127 204 25
-8 -7 11 127 204 25
1 -7 11 127 204 25
7 -7 11 127 204 25
1 -6 11 127 204 25
7 -6 11 127 204 25
7 -5 11 127 204 25
7 -4 11 127 204 25
1 -3 11 127 204 25
7 -3 11 127 204 25
1 -2 11 127 204 25
7 -2 11 127 204 25
1 -1 11 127 204 25
7 -1 11 127 204 25
1 0 11 127 204 25
2 0 11 127 204 25
3 0 11 127 204 25
6 0 11 127 204 25
7 0 11 127 204 25
1 1 11 127 204 25
7 1 11 127 204 25
1 2 11 127 204 25
7 2 11 127 204 25
7 3 11 127 204 25
7 4 11 127 204 25
1 5 11 127 204 25
7 5 11 127 204 25
-8 6 11 127 204 25
1 6 11 127 204 25
7 6 11 127 204 25
-7 7 11 127 204 25
2 7 11 127 204 25
3 7 11 127 204 25
4 7 11 127 204 25
5 7 11 127 204 25
6 7 11 127 204 25
-7 -8 12 127 204 25
2 -8 12 127 204 25
3 -8 12 127 204 25
4 -8 12 127 204 25
5 -8 12 127 204 25
6 -8 12 127 204 25
-8 -7 12 127 204 25
1 -7 12 127 204 25
7 -7 12 127 204 25
1 -6 12 127 204 25
7 -6 12 127 204 25
7 -5 12 127 204 25
7 -4 12 127 204 25
1 -3 12 127 204 25
7 -3 12 127 204 25
1 -2 12 127 204 25
7 -2 12 127 204 25
1 -1 12 127 204 25
7 -1 12 127 204 25
1 0 12 127 204 25
2 0 12 127 204 25
3 0 12 127 204 25
6 0 12 127 204 25
7 0 12 127 204 25
1 1 12 127 204 25
7 1 12 127 204 25
1 2 12 127 204 25
7 2 12 127 204 25
7 3 12 127 204 25
7 4 12 127 204 25
1 5 12 127 204 25
7 5 12 127 204 25
-8 6 12 127 204 25
1 6 12 127 204 25
7 6 12 127 204 25
-7 7 12 127 204 25
2 7 12 127 204 25
3 7 12 127 204 25
4 7 12 127 204 25
5 7 12 127 204 25
6 7 12 127 204 25
-7 -8 13 127 204 25
-6 -8 13 127 204 25
-5 -8 13 127 204 25
-4 -8 13 127 204 25
-3 -8 13 127 204 25
-2 -8 13 127 204 25
-1 -8 13 127 204 25
0 -8 13 127 204 25
1 -8 13 127 204 25
2 -8 13 127 204 25
3 -8 13 127 204 25
4 -8 13 127 204 25
5 -8 13 127 204 25
6 -8 13 127 204 25
-8 -7 13 127 204 25
1 -7 13 127 204 25
7 -7 13 127 204 25
-8 -6 13 127 204 25
1 -6 13 127 204 25
7 -6 13 127 204 25
-8 -5 13 127 204 25
1 -5 13 127 204 25
7 -5 13 127 204 25
-8 -4 13 127 204 25
1 -4 13 127 204 25
7 -4 13 127 204 25
-8 -3 13 127 204 25
1 -3 13 127 204 25
7 -3 13 127 204 25
-8 -2 13 127 204 25
1 -2 13 127 204 25
7 -2 13 127 204 25
-8 -1 13 127 204 25
1 -1 13 127 204 25
7 -1 13 127 204 25
-8 0 13 127 204 25
1 0 13 127 204 25
7 0 13 127 204 25
-8 1 13 127 204 25
1 1 13 127 204 25
7 1 13 127 204 25
-8 2 13 127 204 25
1 2 13 127 204 25
7 2 13 127 204 25
-8 3 13 127 204 25
1 3 13 127 204 25
7 3 13 127 204 25
-8 4 13 127 204 25
1 4 13 127 204 25
7 4 13 127 204 25
-8 5 13 127 204 25
1 5 13 127 204 25
7 5 13 127 204 25
-8 6 13 127 204 25
1 6 13 127 204 25
7 6 13 127 204 25
-7 7 13 127 204 25
-6 7 13 127 204 25
-5 7 13 127 204 25
-4 7 13 127 204 25
-3 7 13 127 204 25
-2 7 13 127 204 25
-1 7 13 127 204 25
0 7 13 127 204 25
1 7 13 127 204 25
2 7 13 127 204 25
3 7 13 127 204 25
4 7 13 127 204 25
5 7 13 127 204 25
6 7 13 127 204 25
2 -7 14 127 204 25
3 -7 14 127 204 25
4 -7 14 127 204 25
5 -7 14 127 204 25
6 -7 14 127 204 25
2 -6 14 127 204 25
3 -6 14 127 204 25
4 -6 14 127 204 25
5 -6 14 127 204 25
6 -6 14 127 204 25
2 -5 14 127 204 25
3 -5 14 127 204 25
4 -5 14 127 204 25
5 -5 14 127 204 25
6 -5 14 127 204 25
2 -4 14 127 204 25
3 -4 14 127 204 25
4 -4 14 127 204 25
5 -4 14 127 204 25
6 -4 14 127 204 25
2 -3 14 127 204 25
3 -3 14 127 204 25
4 -3 14 127 204 25
5 -3 14 127 204 25
6 -3 14 127 204 25
2 -2 14 127 204 25
3 -2 14 127 204 25
4 -2 14 127 204 25
5 -2 14 127 204 25
6 -2 14 127 204 25
2 -1 14 127 204 25
3 -1 14 127 204 25
4 -1 14 127 204 25
5 -1 14 127 204 25
6 -1 14 127 204 25
2 0 14 127 204 25
3 0 14 127 204 25
4 0 14 127 204 25
5 0 14 127 204 25
6 0 14 127 204 25
2 1 14 127 204 25
3 1 14 127 204 25
4 1 14 127 204 25
5 1 14 127 204 25
6 1 14 127 204 25
2 2 14 127 204 25
3 2 14 127 204 25
4 2 14 127 204 25
5 2 14 127 204 25
6 2 14 127 204 25
2 3 14 127 204 25
3 3 14 127 204 25
4 3 14 127 204 25
5 3 14 127 204 25
6 3 14 127 204 25
2 4 14 127 204 25
3 4 14 127 204 25
4 4 14 127 204 25
5 4 14 127 204 25
6 4 14 127 204 25
2 5 14 127 204 25
3 5 14 127 204 25
4 5 14 127 204 25
5 5 14 127 204 25
6 5 14 127 204 25
2 6 14 127 204 25
3 6 14 127 204 25
4 6 14 127 204 25
5 6 14 127 204 25
6 6 14 127 204 25
